Workbook

Sheet Overview
A1: QueryMind - Research Results Workbook
A2: Supporting numerical results for: QueryMind: Design and Evaluation of Secure and Privacy-Preserving Text-to-SQL Using Schema-Aware RAG and LLMs (3ICT 2026, under revision)
A4: Purpose: Every number used in the Experimental Setup, Evaluation, Results, Statistical Analysis, Security Evaluation and Discussion sections, traceable to
A5: saved evidence in the QueryMind repository.
A6: Provenance: Generated by build_workbook.py (same folder) from exp_runs/, exp_com_res/ and experiment/. No result was regenerated, estimated or edited. Blue text =
A7: copied from saved evidence; black text = Excel formula; shaded orange rows = secondary / exploratory / not comparable.
A8: Limitations: One benchmark (32 questions on the classic-models database), one database server, one laptop GPU (4 GB), temperature 0. Execution-result accuracy is
A9: not proof of semantic correctness.
A11: Headline results (linked to the detail sheets)
A12: Result | B12: Correct | C12: Trials | D12: Accuracy | E12: CI low | F12: CI high | G12: SQL execution success rate | H12: Hallucination rate | I12: End-to-end mean (s) | J12: Detail sheet
A13: QueryMind P1 gemma3:1b + mxbai | B13: ='Model Comparison'!G17 | C13: ='Model Comparison'!F17 | D13: ='Model Comparison'!H17 | E13: ='Model Comparison'!I17 | F13: ='Model Comparison'!J17 | G13: ='Model Comparison'!L17 | H13: ='Model Comparison'!O17 | I13: ='Response Time'!G17 | J13: Model Comparison / Response Time
A14: QueryMind P2 gemma3:1b + MiniLM | B14: ='Model Comparison'!G18 | C14: ='Model Comparison'!F18 | D14: ='Model Comparison'!H18 | E14: ='Model Comparison'!I18 | F14: ='Model Comparison'!J18 | G14: ='Model Comparison'!L18 | H14: ='Model Comparison'!O18 | I14: ='Response Time'!G18 | J14: Model Comparison / Response Time
A15: QueryMind P3 qwen3:1.7b + mxbai | B15: ='Model Comparison'!G19 | C15: ='Model Comparison'!F19 | D15: ='Model Comparison'!H19 | E15: ='Model Comparison'!I19 | F15: ='Model Comparison'!J19 | G15: ='Model Comparison'!L19 | H15: ='Model Comparison'!O19 | I15: ='Response Time'!G19 | J15: Model Comparison / Response Time
A16: QueryMind P4 qwen3:1.7b + MiniLM | B16: ='Model Comparison'!G20 | C16: ='Model Comparison'!F20 | D16: ='Model Comparison'!H20 | E16: ='Model Comparison'!I20 | F16: ='Model Comparison'!J20 | G16: ='Model Comparison'!L20 | H16: ='Model Comparison'!O20 | I16: ='Response Time'!G20 | J16: Model Comparison / Response Time
A17: QueryMind P5 llama3.1:8b + mxbai | B17: ='Model Comparison'!G21 | C17: ='Model Comparison'!F21 | D17: ='Model Comparison'!H21 | E17: ='Model Comparison'!I21 | F17: ='Model Comparison'!J21 | G17: ='Model Comparison'!L21 | H17: ='Model Comparison'!O21 | I17: ='Response Time'!G21 | J17: Model Comparison / Response Time
A18: SQLCoder comparison: QueryMind P5 (primary) | B18: ='SQLCoder Comparison'!E18 | C18: ='SQLCoder Comparison'!D18 | D18: ='SQLCoder Comparison'!F18 | E18: ='SQLCoder Comparison'!G18 | F18: ='SQLCoder Comparison'!H18 | G18: ='SQLCoder Comparison'!J18 | H18: ='SQLCoder Comparison'!M18 | J18: SQLCoder Comparison
A19: SQLCoder comparison: SQLCoder-8B original (primary) | B19: ='SQLCoder Comparison'!E19 | C19: ='SQLCoder Comparison'!D19 | D19: ='SQLCoder Comparison'!F19 | E19: ='SQLCoder Comparison'!G19 | F19: ='SQLCoder Comparison'!H19 | G19: ='SQLCoder Comparison'!J19 | H19: ='SQLCoder Comparison'!M19 | J19: SQLCoder Comparison
A20: SQLCoder comparison: SQLCoder-8B dialect-adjusted (SECONDARY, EXPLORATORY) | B20: ='SQLCoder Comparison'!E20 | C20: ='SQLCoder Comparison'!D20 | D20: ='SQLCoder Comparison'!F20 | E20: ='SQLCoder Comparison'!G20 | F20: ='SQLCoder Comparison'!H20 | G20: ='SQLCoder Comparison'!J20 | H20: ='SQLCoder Comparison'!M20 | J20: SQLCoder Comparison
A21: SQLCoder mean time is intentionally not listed here: its overall mean is cached-prompt dominated (see 'Response Time' sections C-D).
A23: Security checks passed / total | B23: ='Security Evaluation'!C22 | C23: ='Security Evaluation'!B22
A25: Recall@1 / @3 / @5, mxbai-embed-large | B25: ='Retrieval Performance'!B14 | C25: ='Retrieval Performance'!B15 | D25: ='Retrieval Performance'!B16
A26: Recall@1 / @3 / @5, all-minilm | B26: ='Retrieval Performance'!C14 | C26: ='Retrieval Performance'!C15 | D26: ='Retrieval Performance'!C16
A29: Workbook map
A30: Sheet | B30: Contents | C30: Primary source
A31: Overview | B31: This sheet: headline numbers, setup, evidence inventory | C31: -
A32: Model Comparison | B32: Five configurations: accuracy, CI, execution success, hallucination, difficulty, stability. Chart 1 | C32: analysis_paper-v1_final + Raw Data
A33: Response Time | B33: Stage breakdown, dispersion, first exposure vs cached prompt, latency control. Charts 2-3 | C33: analysis_paper-v1_final, comparison_sqlcoder-vs-querymind
A34: Retrieval Performance | B34: Recall@1/3/5 for both embedding models. Chart 4 | C34: Raw Data, analysis_paper-v1_final
A35: Statistical Analysis | B35: CIs, pairwise exact McNemar tests, paired bootstrap | C35: analysis_paper-v1_final, compare_baseline (recomputed block)
A36: SQLCoder Comparison | B36: QueryMind P5 vs SQLCoder original vs dialect-adjusted (exploratory). Chart 5 | C36: comparison.json, followup.json, validation.json
A37: Security Evaluation | B37: 103 security checks, false-positive replay, provenance of runs | C37: security_20261018T070742Z
A38: Original vs Expanded | B38: Historical pilot, 75-trial bridge, 480-trial benchmark. Chart 6 | C38: exp_com_res, analysis_bridge-gold5
A39: Raw Data | B39: All 651 trial rows used by the formulas | C39: exp_runs/*/trials.jsonl
A42: Experimental setup (from run_metadata.json of run P5 and the SQLCoder run)
A43: Item | B43: Value
A44: Benchmark | B44: 32 questions, 19 SQL categories, difficulty tiers easy/medium/hard (experiment/benchmark_30.json)
A45: Repeats / trials | B45: 3 repeats; 5 configurations x 32 questions x 3 repeats = 480 trials (+ 75 bridge trials, 96 SQLCoder trials)
A46: Decoding | B46: temperature 0.0, seed 42, timeout 300 s
A47: Retrieval | B47: top_k 5, cosine distance, one chunk per table (CREATE TABLE), Recall@K for K in [1, 3, 5]
A48: Evaluation metric | B48: execution-result accuracy (result equivalence with the reference query); statement timeout 60 s; read-only transaction
...

Sheet Model Comparison
A1: Model Comparison - five QueryMind configurations (expanded benchmark)
A2: 3 LLMs x 2 embedding models (5 evaluated), 32 questions x 3 repeats = 96 trials per configuration, 480 trials in total
A4: Source: Counts and means are formulas over 'Raw Data' (copied from exp_runs/*_paper-v1-P1..P5/trials.jsonl). Confidence intervals, status breakdowns,
A5: difficulty tiers and repeat statistics are copied from exp_runs/analysis_paper-v1_final/analysis.json.
A6: Method: Primary metric = execution-result accuracy (result equivalence with the reference query on one database state; it is not proof of semantic
A7: correctness). CI = 95% percentile bootstrap that resamples the 32 questions (cluster bootstrap, 10,000 resamples, seed 42). temperature 0, seed 42,
A8: top_k 5, cosine distance, one chunk per table, MariaDB 10.11.13 (classicmodels_gold).
A9: Sample size: 32 questions x 3 repeats = 96 trials per configuration. The three repeats are not independent samples (the same question is repeated), so the Wilson
A10: interval on 'Statistical Analysis' is shown for reference only; use the cluster-bootstrap CI.
A11: Limitations: One database, one benchmark of 32 questions, one hardware setup (Ryzen 7 5800H, 15 GiB, RTX 3050 4 GB). Gemma3 1B has a high hallucination rate.
A12: Accuracy of the three repeats is near-identical because decoding is deterministic at temperature 0.
A13: Legend: Blue text = value copied from saved evidence; black text = Excel formula.
A15: A. Accuracy, execution success and hallucination (chart data)
A16: Configuration | B16: LLM | C16: Embedding model | D16: Questions | E16: Repeats | F16: Total trials | G16: Correct results | H16: Execution-result accuracy | I16: 95% CI low (cluster bootstrap) | J16: 95% CI high (cluster bootstrap) | K16: SQL executed | L16: SQL execution success rate | M16: Database errors | N16: Hallucinated identifiers | O16: Hallucination rate | P16: Executed but incorrect | Q16: CI error bar + (chart) | R16: CI error bar - (chart) | S16: Source
A17: P1 gemma3:1b + mxbai | B17: gemma3:1b | C17: mxbai-embed-large:latest | D17: 32 | E17: 3 | F17: =D17*E17 | G17: =COUNTIFS('Raw Data'!$A$12:$A$662,"Expanded 32q",'Raw Data'!$C$12:$C$662,"P1",'Raw Data'!$K$12:$K$662,1) | H17: =G17/F17 | I17: 0.09375 | J17: 0.40625 | K17: =COUNTIFS('Raw Data'!$A$12:$A$662,"Expanded 32q",'Raw Data'!$C$12:$C$662,"P1",'Raw Data'!$J$12:$J$662,1) | L17: =K17/F17 | M17: =COUNTIFS('Raw Data'!$A$12:$A$662,"Expanded 32q",'Raw Data'!$C$12:$C$662,"P1",'Raw Data'!$I$12:$I$662,"db_error") | N17: =COUNTIFS('Raw Data'!$A$12:$A$662,"Expanded 32q",'Raw Data'!$C$12:$C$662,"P1",'Raw Data'!$L$12:$L$662,1) | O17: =N17/F17 | P17: =K17-G17 | Q17: =J17-H17 | R17: =H17-I17 | S17: exp_runs/analysis_paper-v1_final/analysis.json (CI, questions, repeats); exp_runs/20261017T112626Z_paper-v1-P1/trials.jsonl (counts)
A18: P2 gemma3:1b + MiniLM | B18: gemma3:1b | C18: all-minilm:latest | D18: 32 | E18: 3 | F18: =D18*E18 | G18: =COUNTIFS('Raw Data'!$A$12:$A$662,"Expanded 32q",'Raw Data'!$C$12:$C$662,"P2",'Raw Data'!$K$12:$K$662,1) | H18: =G18/F18 | I18: 0.125 | J18: 0.4375 | K18: =COUNTIFS('Raw Data'!$A$12:$A$662,"Expanded 32q",'Raw Data'!$C$12:$C$662,"P2",'Raw Data'!$J$12:$J$662,1) | L18: =K18/F18 | M18: =COUNTIFS('Raw Data'!$A$12:$A$662,"Expanded 32q",'Raw Data'!$C$12:$C$662,"P2",'Raw Data'!$I$12:$I$662,"db_error") | N18: =COUNTIFS('Raw Data'!$A$12:$A$662,"Expanded 32q",'Raw Data'!$C$12:$C$662,"P2",'Raw Data'!$L$12:$L$662,1) | O18: =N18/F18 | P18: =K18-G18 | Q18: =J18-H18 | R18: =H18-I18 | S18: exp_runs/analysis_paper-v1_final/analysis.json (CI, questions, repeats); exp_runs/20261017T113614Z_paper-v1-P2/trials.jsonl (counts)
A19: P3 qwen3:1.7b + mxbai | B19: qwen3:1.7b | C19: mxbai-embed-large:latest | D19: 32 | E19: 3 | F19: =D19*E19 | G19: =COUNTIFS('Raw Data'!$A$12:$A$662,"Expanded 32q",'Raw Data'!$C$12:$C$662,"P3",'Raw Data'!$K$12:$K$662,1) | H19: =G19/F19 | I19: 0.84375 | J19: 0.98958333 | K19: =COUNTIFS('Raw Data'!$A$12:$A$662,"Expanded 32q",'Raw Data'!$C$12:$C$662,"P3",'Raw Data'!$J$12:$J$662,1) | L19: =K19/F19 | M19: =COUNTIFS('Raw Data'!$A$12:$A$662,"Expanded 32q",'Raw Data'!$C$12:$C$662,"P3",'Raw Data'!$I$12:$I$662,"db_error") | N19: =COUNTIFS('Raw Data'!$A$12:$A$662,"Expanded 32q",'Raw Data'!$C$12:$C$662,"P3",'Raw Data'!$L$12:$L$662,1) | O19: =N19/F19 | P19: =K19-G19 | Q19: =J19-H19 | R19: =H19-I19 | S19: exp_runs/analysis_paper-v1_final/analysis.json (CI, questions, repeats); exp_runs/20261017T114545Z_paper-v1-P3/trials.jsonl (counts)
A20: P4 qwen3:1.7b + MiniLM | B20: qwen3:1.7b | C20: all-minilm:latest | D20: 32 | E20: 3 | F20: =D20*E20 | G20: =COUNTIFS('Raw Data'!$A$12:$A$662,"Expanded 32q",'Raw Data'!$C$12:$C$662,"P4",'Raw Data'!$K$12:$K$662,1) | H20: =G20/F20 | I20: 0.79166667 | J20: 0.97916667 | K20: =COUNTIFS('Raw Data'!$A$12:$A$662,"Expanded 32q",'Raw Data'!$C$12:$C$662,"P4",'Raw Data'!$J$12:$J$662,1) | L20: =K20/F20 | M20: =COUNTIFS('Raw Data'!$A$12:$A$662,"Expanded 32q",'Raw Data'!$C$12:$C$662,"P4",'Raw Data'!$I$12:$I$662,"db_error") | N20: =COUNTIFS('Raw Data'!$A$12:$A$662,"Expanded 32q",'Raw Data'!$C$12:$C$662,"P4",'Raw Data'!$L$12:$L$662,1) | O20: =N20/F20 | P20: =K20-G20 | Q20: =J20-H20 | R20: =H20-I20 | S20: exp_runs/analysis_paper-v1_final/analysis.json (CI, questions, repeats); exp_runs/20261017T122858Z_paper-v1-P4/trials.jsonl (counts)
A21: P5 llama3.1:8b + mxbai | B21: llama3.1:8b | C21: mxbai-embed-large:latest | D21: 32 | E21: 3 | F21: =D21*E21 | G21: =COUNTIFS('Raw Data'!$A$12:$A$662,"Expanded 32q",'Raw Data'!$C$12:$C$662,"P5",'Raw Data'!$K$12:$K$662,1) | H21: =G21/F21 | I21: 0.78125 | J21: 1 | K21: =COUNTIFS('Raw Data'!$A$12:$A$662,"Expanded 32q",'Raw Data'!$C$12:$C$662,"P5",'Raw Data'!$J$12:$J$662,1) | L21: =K21/F21 | M21: =COUNTIFS('Raw Data'!$A$12:$A$662,"Expanded 32q",'Raw Data'!$C$12:$C$662,"P5",'Raw Data'!$I$12:$I$662,"db_error") | N21: =COUNTIFS('Raw Data'!$A$12:$A$662,"Expanded 32q",'Raw Data'!$C$12:$C$662,"P5",'Raw Data'!$L$12:$L$662,1) | O21: =N21/F21 | P21: =K21-G21 | Q21: =J21-H21 | R21: =H21-I21 | S21: exp_runs/analysis_paper-v1_final/analysis.json (CI, questions, repeats); exp_runs/20261017T131359Z_paper-v1-P5/trials.jsonl (counts)
A41: Chart 1 data: table A, columns H (accuracy), Q-R (CI half-widths from I-J). Error bars = 95% cluster-bootstrap CI. Source: exp_runs/analysis_paper-v1_final/analysis.json
A42: B. Outcome breakdown per configuration
A43: Source: analysis.json -> configs[...].status_counts, db_error_breakdown, executed_but_wrong_breakdown
A44: Configuration | B44: Executed | C44: Database error | D44: Retrieval error | E44: Generation error | F44: Validation failure | G44: DB error: ambiguous_column | H44: DB error: hallucinated_identifier | I44: DB error: permission_denied_invalid_reference | J44: DB error: unsupported_mariadb_feature | K44: Executed, wrong: column_count_mismatch | L44: Executed, wrong: content_mismatch | M44: Executed, wrong: row_count_mismatch
A45: P1 gemma3:1b + mxbai | B45: 69 | C45: 27 | D45: 0 | E45: 0 | F45: 0 | G45: 0 | H45: 24 | I45: 3 | J45: 0 | K45: 9 | L45: 3 | M45: 33
A46: P2 gemma3:1b + MiniLM | B46: 72 | C46: 24 | D46: 0 | E46: 0 | F46: 0 | G46: 0 | H46: 18 | I46: 3 | J46: 3 | K46: 12 | L46: 0 | M46: 33
A47: P3 qwen3:1.7b + mxbai | B47: 94 | C47: 2 | D47: 0 | E47: 0 | F47: 0 | G47: 2 | H47: 0 | I47: 0 | J47: 0 | K47: 0 | L47: 3 | M47: 2
A48: P4 qwen3:1.7b + MiniLM | B48: 91 | C48: 5 | D48: 0 | E48: 0 | F48: 0 | G48: 3 | H48: 2 | I48: 0 | J48: 0 | K48: 0 | L48: 5 | M48: 0
A49: P5 llama3.1:8b + mxbai | B49: 93 | C49: 3 | D49: 0 | E49: 0 | F49: 0 | G49: 0 | H49: 3 | I49: 0 | J49: 0 | K49: 0 | L49: 0 | M49: 6
A52: C. Accuracy by difficulty tier
A53: Source: analysis.json -> configs[...].difficulty_accuracy (tiers: experiment/difficulty_tiers.json)
A54: Configuration | B54: Easy: trials | C54: Easy: accuracy | D54: Medium: trials | E54: Medium: accuracy | F54: Hard: trials | G54: Hard: accuracy
A55: P1 gemma3:1b + mxbai | B55: 48 | C55: 0.3125 | D55: 33 | E55: 0.18181818 | F55: 15 | G55: 0.2
A56: P2 gemma3:1b + MiniLM | B56: 48 | C56: 0.3125 | D56: 33 | E56: 0.18181818 | F56: 15 | G56: 0.4
A57: P3 qwen3:1.7b + mxbai | B57: 48 | C57: 1 | D57: 33 | E57: 0.84848485 | F57: 15 | G57: 0.86666667
A58: P4 qwen3:1.7b + MiniLM | B58: 48 | C58: 1 | D58: 33 | E58: 0.84848485 | F58: 15 | G58: 0.66666667
A59: P5 llama3.1:8b + mxbai | B59: 48 | C59: 0.875 | D59: 33 | E59: 1 | F59: 15 | G59: 0.8
A62: D. Stability across the three repeats
A63: Source: analysis.json -> configs[...].accuracy_by_repeat, accuracy_stdev_across_repeats, identical_sql_across_repeats_rate, questions_*
A64: Configuration | B64: Accuracy repeat 1 | C64: Accuracy repeat 2 | D64: Accuracy repeat 3 | E64: SD across repeats | F64: Questions with identical SQL in all repeats | G64: Questions always correct | H64: Questions never correct | I64: Questions inconsistent
A65: P1 gemma3:1b + mxbai | B65: 0.25 | C65: 0.25 | D65: 0.25 | E65: 0 | F65: 0.96875 | G65: 8 | H65: 24 | I65: 0
...

Sheet Response Time
A1: Response Time - stage breakdown, first exposure versus cached prompt
A2: Seconds per query on the evaluation hardware (Ryzen 7 5800H, RTX 3050 4 GB, Ollama 0.12.1)
A4: Source: Means in table A are formulas over 'Raw Data'. Median, SD, min and max are copied from exp_runs/analysis_paper-v1_final/analysis.json
A5: (latency_seconds). Sections C-F come from exp_runs/comparison_sqlcoder-vs-querymind/comparison.json and the latency-control run.
A6: Method: End-to-end = retrieval + generation + database execution (time_total_s). The 480 QueryMind trials were run once on a warm machine; Ollama's internal
A7: load / prompt-evaluation timings were NOT recorded for them (only for SQLCoder and the 8-question control run).
A8: Cold vs cached: Repeat 1 of SQLCoder evaluates a ~1,300-token full-schema prompt from scratch (prompt eval mean 43.9 s); repeats 2 and 3 reuse Ollama's cached
A9: evaluation of the identical prompt (0.18 s). SQLCoder's overall mean (20.5 s) is therefore dominated by cached repeats and MUST NOT be used to claim
A10: that SQLCoder is faster than QueryMind. Compare first-exposure latency (section D).
A11: Limitations: One machine, one GPU with 4 GB (llama3.1:8b and SQLCoder-8B are partly offloaded); timings are not comparable with other hardware. The retrieval stage
A12: includes the embedding call and ChromaDB lookup as implemented in chroma_rag.py.
A13: Legend: Blue text = copied from saved evidence; black text = formula.
A15: A. Mean time per stage (chart 2 data)
A16: Configuration | B16: Trials | C16: Retrieval mean (s) | D16: Generation mean (s) | E16: DB execution mean (s) | F16: Sum of stages (s) | G16: End-to-end mean (s) | H16: Unattributed time: end-to-end - sum of stages (s) | I16: Source
A17: P1 gemma3:1b + mxbai | B17: =COUNTIFS('Raw Data'!$A$12:$A$662,"Expanded 32q",'Raw Data'!$C$12:$C$662,"P1") | C17: =AVERAGEIFS('Raw Data'!$P$12:$P$662,'Raw Data'!$A$12:$A$662,"Expanded 32q",'Raw Data'!$C$12:$C$662,"P1") | D17: =AVERAGEIFS('Raw Data'!$Q$12:$Q$662,'Raw Data'!$A$12:$A$662,"Expanded 32q",'Raw Data'!$C$12:$C$662,"P1") | E17: =AVERAGEIFS('Raw Data'!$R$12:$R$662,'Raw Data'!$A$12:$A$662,"Expanded 32q",'Raw Data'!$C$12:$C$662,"P1") | F17: =C17+D17+E17 | G17: =AVERAGEIFS('Raw Data'!$S$12:$S$662,'Raw Data'!$A$12:$A$662,"Expanded 32q",'Raw Data'!$C$12:$C$662,"P1") | H17: =G17-F17 | I17: exp_runs/20261017T112626Z_paper-v1-P1/trials.jsonl
A18: P2 gemma3:1b + MiniLM | B18: =COUNTIFS('Raw Data'!$A$12:$A$662,"Expanded 32q",'Raw Data'!$C$12:$C$662,"P2") | C18: =AVERAGEIFS('Raw Data'!$P$12:$P$662,'Raw Data'!$A$12:$A$662,"Expanded 32q",'Raw Data'!$C$12:$C$662,"P2") | D18: =AVERAGEIFS('Raw Data'!$Q$12:$Q$662,'Raw Data'!$A$12:$A$662,"Expanded 32q",'Raw Data'!$C$12:$C$662,"P2") | E18: =AVERAGEIFS('Raw Data'!$R$12:$R$662,'Raw Data'!$A$12:$A$662,"Expanded 32q",'Raw Data'!$C$12:$C$662,"P2") | F18: =C18+D18+E18 | G18: =AVERAGEIFS('Raw Data'!$S$12:$S$662,'Raw Data'!$A$12:$A$662,"Expanded 32q",'Raw Data'!$C$12:$C$662,"P2") | H18: =G18-F18 | I18: exp_runs/20261017T113614Z_paper-v1-P2/trials.jsonl
A19: P3 qwen3:1.7b + mxbai | B19: =COUNTIFS('Raw Data'!$A$12:$A$662,"Expanded 32q",'Raw Data'!$C$12:$C$662,"P3") | C19: =AVERAGEIFS('Raw Data'!$P$12:$P$662,'Raw Data'!$A$12:$A$662,"Expanded 32q",'Raw Data'!$C$12:$C$662,"P3") | D19: =AVERAGEIFS('Raw Data'!$Q$12:$Q$662,'Raw Data'!$A$12:$A$662,"Expanded 32q",'Raw Data'!$C$12:$C$662,"P3") | E19: =AVERAGEIFS('Raw Data'!$R$12:$R$662,'Raw Data'!$A$12:$A$662,"Expanded 32q",'Raw Data'!$C$12:$C$662,"P3") | F19: =C19+D19+E19 | G19: =AVERAGEIFS('Raw Data'!$S$12:$S$662,'Raw Data'!$A$12:$A$662,"Expanded 32q",'Raw Data'!$C$12:$C$662,"P3") | H19: =G19-F19 | I19: exp_runs/20261017T114545Z_paper-v1-P3/trials.jsonl
A20: P4 qwen3:1.7b + MiniLM | B20: =COUNTIFS('Raw Data'!$A$12:$A$662,"Expanded 32q",'Raw Data'!$C$12:$C$662,"P4") | C20: =AVERAGEIFS('Raw Data'!$P$12:$P$662,'Raw Data'!$A$12:$A$662,"Expanded 32q",'Raw Data'!$C$12:$C$662,"P4") | D20: =AVERAGEIFS('Raw Data'!$Q$12:$Q$662,'Raw Data'!$A$12:$A$662,"Expanded 32q",'Raw Data'!$C$12:$C$662,"P4") | E20: =AVERAGEIFS('Raw Data'!$R$12:$R$662,'Raw Data'!$A$12:$A$662,"Expanded 32q",'Raw Data'!$C$12:$C$662,"P4") | F20: =C20+D20+E20 | G20: =AVERAGEIFS('Raw Data'!$S$12:$S$662,'Raw Data'!$A$12:$A$662,"Expanded 32q",'Raw Data'!$C$12:$C$662,"P4") | H20: =G20-F20 | I20: exp_runs/20261017T122858Z_paper-v1-P4/trials.jsonl
A21: P5 llama3.1:8b + mxbai | B21: =COUNTIFS('Raw Data'!$A$12:$A$662,"Expanded 32q",'Raw Data'!$C$12:$C$662,"P5") | C21: =AVERAGEIFS('Raw Data'!$P$12:$P$662,'Raw Data'!$A$12:$A$662,"Expanded 32q",'Raw Data'!$C$12:$C$662,"P5") | D21: =AVERAGEIFS('Raw Data'!$Q$12:$Q$662,'Raw Data'!$A$12:$A$662,"Expanded 32q",'Raw Data'!$C$12:$C$662,"P5") | E21: =AVERAGEIFS('Raw Data'!$R$12:$R$662,'Raw Data'!$A$12:$A$662,"Expanded 32q",'Raw Data'!$C$12:$C$662,"P5") | F21: =C21+D21+E21 | G21: =AVERAGEIFS('Raw Data'!$S$12:$S$662,'Raw Data'!$A$12:$A$662,"Expanded 32q",'Raw Data'!$C$12:$C$662,"P5") | H21: =G21-F21 | I21: exp_runs/20261017T131359Z_paper-v1-P5/trials.jsonl
A41: Chart 2 data: table A columns C-E (formulas over Raw Data). DB execution (~0.0005 s) is not visible at this scale.
A42: B. Dispersion of end-to-end, retrieval and generation time
A43: Source: analysis.json -> configs[...].latency_seconds (all 96 trials each)
A44: Configuration | B44: End-to-end mean (s) | C44: End-to-end median (s) | D44: End-to-end SD (s) | E44: End-to-end min (s) | F44: End-to-end max (s) | G44: Retrieval median (s) | H44: Retrieval SD (s) | I44: Generation median (s) | J44: Generation SD (s)
A45: P1 gemma3:1b + mxbai | B45: 5.9444146 | C45: 6.0295135 | D45: 0.71029563 | E45: 4.397455 | F45: 7.5544793 | G45: 0.082284058 | H45: 0.04377734 | I45: 5.9531808 | J45: 0.70089976
A46: P2 gemma3:1b + MiniLM | B46: 5.9223401 | C46: 5.9962716 | D46: 0.65266898 | E46: 4.3821996 | F46: 7.1201882 | G46: 0.032095083 | H46: 0.0016334274 | I46: 5.9625975 | J46: 0.65186886
A47: P3 qwen3:1.7b + mxbai | B47: 26.745266 | C47: 22.836377 | D47: 18.847125 | E47: 10.855791 | F47: 119.55607 | G47: 0.089667038 | H47: 0.040788948 | I47: 22.751428 | J47: 18.831328
A48: P4 qwen3:1.7b + MiniLM | B48: 28.06887 | C48: 20.180979 | D48: 22.431947 | E48: 9.0096845 | F48: 131.56344 | G48: 0.044096016 | H48: 0.0034531206 | I48: 20.139701 | J48: 22.431631
A49: P5 llama3.1:8b + mxbai | B49: 43.156036 | C49: 43.671223 | D49: 3.0786855 | E49: 37.278117 | F49: 49.905632 | G49: 5.3737966 | H49: 0.022071041 | I49: 38.300334 | J49: 3.066125
A52: C. Latency by repeat - first exposure (repeat 1) versus repeated identical prompts (chart 3 data)
A53: Source: comparison.json -> latency_by_repeat (32 questions per repeat). Ollama prompt-eval was recorded only for SQLCoder.
A54: System | B54: Repeat | C54: Questions (n) | D54: End-to-end mean (s) | E54: End-to-end median (s) | F54: Generation mean (s) | G54: Ollama prompt eval mean (s) | H54: Interpretation
A55: QueryMind P5 (Llama 3.1 8B + mxbai) | B55: 1 | C55: 32 | D55: 43.154265 | E55: 43.795559 | F55: 37.773539 | H55: Prompt-eval timings not recorded for the 480-trial runs; end-to-end time is unchanged across repeats
A56: QueryMind P5 (Llama 3.1 8B + mxbai) | B56: 2 | C56: 32 | D56: 43.150945 | E56: 43.606 | F56: 37.768946 | H56: Prompt-eval timings not recorded for the 480-trial runs; end-to-end time is unchanged across repeats
A57: QueryMind P5 (Llama 3.1 8B + mxbai) | B57: 3 | C57: 32 | D57: 43.162899 | E57: 43.669005 | F57: 37.782256 | H57: Prompt-eval timings not recorded for the 480-trial runs; end-to-end time is unchanged across repeats
A58: SQLCoder-8B original | B58: 1 | C58: 32 | D58: 49.700738 | E58: 49.510163 | F58: 49.699896 | G58: 43.850437 | H58: First exposure: full-schema prompt evaluated from scratch
A59: SQLCoder-8B original | B59: 2 | C59: 32 | D59: 5.9445129 | E59: 5.5926488 | F59: 5.9438984 | G59: 0.17887428 | H59: Cached prompt: Ollama reuses the evaluated identical prompt
A60: SQLCoder-8B original | B60: 3 | C60: 32 | D60: 5.9934679 | E60: 5.5962259 | F60: 5.9928566 | G60: 0.17723064 | H60: Cached prompt: Ollama reuses the evaluated identical prompt
A80: Chart 3 data: pivot block below (formulas over section C). Source: exp_runs/comparison_sqlcoder-vs-querymind/comparison.json
A81: Chart 3 pivot (formulas over the table above)
A82: Repeat | B82: QueryMind P5 end-to-end mean (s) | C82: SQLCoder original end-to-end mean (s)
...

Sheet Retrieval Performance
A1: Retrieval Performance - Recall@K of schema retrieval
A2: Share of the tables a question needs that appear in the top-K retrieved tables (one chunk per table)
A4: Source: Recall values are formulas (AVERAGEIFS) over 'Raw Data' (recall_by_k of exp_runs/*_paper-v1-P*/trials.jsonl and *_bridge-gold5-P*/trials.jsonl). Full-
A5: recall and recall-versus-correctness figures are copied from exp_runs/analysis_paper-v1_final/analysis.json.
A6: Method: Recall@K = fraction of the question's required tables found among the K highest-ranked tables, averaged over trials. The database has 8 tables; the
A7: application retrieves K = 5. Retrieval is independent of the LLM, so the three mxbai configurations have identical recall.
A8: Sample size: Expanded benchmark: 288 trials with mxbai-embed-large, 192 with all-minilm (32 questions x 3 repeats x 3 or 2 LLMs). Bridge set: 5 questions.
A9: Limitations: Recall@5 is 100% for mxbai on this 8-table schema largely because K = 5 of 8 tables is generous; results will not transfer to large schemas without
A10: testing.
A12: A. Mean Recall@K per embedding model, expanded benchmark (chart 4 data)
A13: Metric | B13: mxbai-embed-large | C13: all-minilm | D13: Difference (mxbai - MiniLM)
A14: Recall@1 | B14: =AVERAGEIFS('Raw Data'!$M$12:$M$662,'Raw Data'!$A$12:$A$662,"Expanded 32q",'Raw Data'!$E$12:$E$662,"mxbai-embed-large:latest") | C14: =AVERAGEIFS('Raw Data'!$M$12:$M$662,'Raw Data'!$A$12:$A$662,"Expanded 32q",'Raw Data'!$E$12:$E$662,"all-minilm:latest") | D14: =B14-C14
A15: Recall@3 | B15: =AVERAGEIFS('Raw Data'!$N$12:$N$662,'Raw Data'!$A$12:$A$662,"Expanded 32q",'Raw Data'!$E$12:$E$662,"mxbai-embed-large:latest") | C15: =AVERAGEIFS('Raw Data'!$N$12:$N$662,'Raw Data'!$A$12:$A$662,"Expanded 32q",'Raw Data'!$E$12:$E$662,"all-minilm:latest") | D15: =B15-C15
A16: Recall@5 | B16: =AVERAGEIFS('Raw Data'!$O$12:$O$662,'Raw Data'!$A$12:$A$662,"Expanded 32q",'Raw Data'!$E$12:$E$662,"mxbai-embed-large:latest") | C16: =AVERAGEIFS('Raw Data'!$O$12:$O$662,'Raw Data'!$A$12:$A$662,"Expanded 32q",'Raw Data'!$E$12:$E$662,"all-minilm:latest") | D16: =B16-C16
A17: Trials per embedding model | B17: =COUNTIFS('Raw Data'!$A$12:$A$662,"Expanded 32q",'Raw Data'!$E$12:$E$662,"mxbai-embed-large:latest") | C17: =COUNTIFS('Raw Data'!$A$12:$A$662,"Expanded 32q",'Raw Data'!$E$12:$E$662,"all-minilm:latest")
A37: Chart 4 data: table A (formulas over Raw Data, 288 mxbai / 192 MiniLM trials). Source: exp_runs/analysis_paper-v1_final/analysis.json
A38: B. Recall per configuration (expanded benchmark, 96 trials each)
A39: Configuration | B39: Embedding model | C39: Recall@1 | D39: Recall@3 | E39: Recall@5 | F39: Trials with all required tables in top-5 | G39: Mean retrieval time (s) | H39: Source
A40: P1 gemma3:1b + mxbai | B40: mxbai-embed-large:latest | C40: =AVERAGEIFS('Raw Data'!$M$12:$M$662,'Raw Data'!$A$12:$A$662,"Expanded 32q",'Raw Data'!$C$12:$C$662,"P1") | D40: =AVERAGEIFS('Raw Data'!$N$12:$N$662,'Raw Data'!$A$12:$A$662,"Expanded 32q",'Raw Data'!$C$12:$C$662,"P1") | E40: =AVERAGEIFS('Raw Data'!$O$12:$O$662,'Raw Data'!$A$12:$A$662,"Expanded 32q",'Raw Data'!$C$12:$C$662,"P1") | F40: 1 | G40: =AVERAGEIFS('Raw Data'!$P$12:$P$662,'Raw Data'!$A$12:$A$662,"Expanded 32q",'Raw Data'!$C$12:$C$662,"P1") | H40: exp_runs/analysis_paper-v1_final/analysis.json (full recall rate)
A41: P2 gemma3:1b + MiniLM | B41: all-minilm:latest | C41: =AVERAGEIFS('Raw Data'!$M$12:$M$662,'Raw Data'!$A$12:$A$662,"Expanded 32q",'Raw Data'!$C$12:$C$662,"P2") | D41: =AVERAGEIFS('Raw Data'!$N$12:$N$662,'Raw Data'!$A$12:$A$662,"Expanded 32q",'Raw Data'!$C$12:$C$662,"P2") | E41: =AVERAGEIFS('Raw Data'!$O$12:$O$662,'Raw Data'!$A$12:$A$662,"Expanded 32q",'Raw Data'!$C$12:$C$662,"P2") | F41: 0.96875 | G41: =AVERAGEIFS('Raw Data'!$P$12:$P$662,'Raw Data'!$A$12:$A$662,"Expanded 32q",'Raw Data'!$C$12:$C$662,"P2") | H41: exp_runs/analysis_paper-v1_final/analysis.json (full recall rate)
A42: P3 qwen3:1.7b + mxbai | B42: mxbai-embed-large:latest | C42: =AVERAGEIFS('Raw Data'!$M$12:$M$662,'Raw Data'!$A$12:$A$662,"Expanded 32q",'Raw Data'!$C$12:$C$662,"P3") | D42: =AVERAGEIFS('Raw Data'!$N$12:$N$662,'Raw Data'!$A$12:$A$662,"Expanded 32q",'Raw Data'!$C$12:$C$662,"P3") | E42: =AVERAGEIFS('Raw Data'!$O$12:$O$662,'Raw Data'!$A$12:$A$662,"Expanded 32q",'Raw Data'!$C$12:$C$662,"P3") | F42: 1 | G42: =AVERAGEIFS('Raw Data'!$P$12:$P$662,'Raw Data'!$A$12:$A$662,"Expanded 32q",'Raw Data'!$C$12:$C$662,"P3") | H42: exp_runs/analysis_paper-v1_final/analysis.json (full recall rate)
A43: P4 qwen3:1.7b + MiniLM | B43: all-minilm:latest | C43: =AVERAGEIFS('Raw Data'!$M$12:$M$662,'Raw Data'!$A$12:$A$662,"Expanded 32q",'Raw Data'!$C$12:$C$662,"P4") | D43: =AVERAGEIFS('Raw Data'!$N$12:$N$662,'Raw Data'!$A$12:$A$662,"Expanded 32q",'Raw Data'!$C$12:$C$662,"P4") | E43: =AVERAGEIFS('Raw Data'!$O$12:$O$662,'Raw Data'!$A$12:$A$662,"Expanded 32q",'Raw Data'!$C$12:$C$662,"P4") | F43: 0.96875 | G43: =AVERAGEIFS('Raw Data'!$P$12:$P$662,'Raw Data'!$A$12:$A$662,"Expanded 32q",'Raw Data'!$C$12:$C$662,"P4") | H43: exp_runs/analysis_paper-v1_final/analysis.json (full recall rate)
A44: P5 llama3.1:8b + mxbai | B44: mxbai-embed-large:latest | C44: =AVERAGEIFS('Raw Data'!$M$12:$M$662,'Raw Data'!$A$12:$A$662,"Expanded 32q",'Raw Data'!$C$12:$C$662,"P5") | D44: =AVERAGEIFS('Raw Data'!$N$12:$N$662,'Raw Data'!$A$12:$A$662,"Expanded 32q",'Raw Data'!$C$12:$C$662,"P5") | E44: =AVERAGEIFS('Raw Data'!$O$12:$O$662,'Raw Data'!$A$12:$A$662,"Expanded 32q",'Raw Data'!$C$12:$C$662,"P5") | F44: 1 | G44: =AVERAGEIFS('Raw Data'!$P$12:$P$662,'Raw Data'!$A$12:$A$662,"Expanded 32q",'Raw Data'!$C$12:$C$662,"P5") | H44: exp_runs/analysis_paper-v1_final/analysis.json (full recall rate)
A47: C. Bridge set (5 original questions x 3 repeats, 15 trials per configuration) - for comparison only
A48: Embedding model | B48: Trials | C48: Recall@1 | D48: Recall@3 | E48: Recall@5
A49: mxbai-embed-large:latest | B49: =COUNTIFS('Raw Data'!$A$12:$A$662,"Bridge 5q",'Raw Data'!$E$12:$E$662,"mxbai-embed-large:latest") | C49: =AVERAGEIFS('Raw Data'!$M$12:$M$662,'Raw Data'!$A$12:$A$662,"Bridge 5q",'Raw Data'!$E$12:$E$662,"mxbai-embed-large:latest") | D49: =AVERAGEIFS('Raw Data'!$N$12:$N$662,'Raw Data'!$A$12:$A$662,"Bridge 5q",'Raw Data'!$E$12:$E$662,"mxbai-embed-large:latest") | E49: =AVERAGEIFS('Raw Data'!$O$12:$O$662,'Raw Data'!$A$12:$A$662,"Bridge 5q",'Raw Data'!$E$12:$E$662,"mxbai-embed-large:latest")
A50: all-minilm:latest | B50: =COUNTIFS('Raw Data'!$A$12:$A$662,"Bridge 5q",'Raw Data'!$E$12:$E$662,"all-minilm:latest") | C50: =AVERAGEIFS('Raw Data'!$M$12:$M$662,'Raw Data'!$A$12:$A$662,"Bridge 5q",'Raw Data'!$E$12:$E$662,"all-minilm:latest") | D50: =AVERAGEIFS('Raw Data'!$N$12:$N$662,'Raw Data'!$A$12:$A$662,"Bridge 5q",'Raw Data'!$E$12:$E$662,"all-minilm:latest") | E50: =AVERAGEIFS('Raw Data'!$O$12:$O$662,'Raw Data'!$A$12:$A$662,"Bridge 5q",'Raw Data'!$E$12:$E$662,"all-minilm:latest")
A53: D. Accuracy when the required tables were / were not fully retrieved
A54: Source: analysis.json -> configs[...].retrieval_vs_correctness (trial counts; accuracy undefined when no partial-recall trials)
A55: Configuration | B55: Retrieval depth | C55: Trials with full recall | D55: Accuracy, full recall | E55: Trials with partial recall | F55: Accuracy, partial recall
A56: P1 gemma3:1b + mxbai | B56: K = 1 | C56: 51 | D56: 0.29411765 | E56: 45 | F56: 0.2
A57: P1 gemma3:1b + mxbai | B57: K = 3 | C57: 87 | D57: 0.27586207 | E57: 9 | F57: 0
A58: P1 gemma3:1b + mxbai | B58: K = 5 | C58: 96 | D58: 0.25 | E58: 0
A59: P2 gemma3:1b + MiniLM | B59: K = 1 | C59: 48 | D59: 0.25 | E59: 48 | F59: 0.3125
A60: P2 gemma3:1b + MiniLM | B60: K = 3 | C60: 90 | D60: 0.26666667 | E60: 6 | F60: 0.5
A61: P2 gemma3:1b + MiniLM | B61: K = 5 | C61: 93 | D61: 0.29032258 | E61: 3 | F61: 0
A62: P3 qwen3:1.7b + mxbai | B62: K = 1 | C62: 51 | D62: 1 | E62: 45 | F62: 0.84444444
A63: P3 qwen3:1.7b + mxbai | B63: K = 3 | C63: 87 | D63: 0.94252874 | E63: 9 | F63: 0.77777778
A64: P3 qwen3:1.7b + mxbai | B64: K = 5 | C64: 96 | D64: 0.92708333 | E64: 0
A65: P4 qwen3:1.7b + MiniLM | B65: K = 1 | C65: 48 | D65: 1 | E65: 48 | F65: 0.79166667
...

Sheet Statistical Analysis
A1: Statistical Analysis - confidence intervals and paired comparisons
A2: Question-level paired tests on the 32-question benchmark
A4: Source: Block A links to 'Model Comparison' and copies Wilson intervals and stability statistics from analysis.json. Block B copies only_first / only_second /
A5: exact_mcnemar_p from analysis.json -> paired_comparisons and re-computes the p-value with an Excel formula as a cross-check. Block C is RECOMPUTED
A6: from the saved trials with experiment/compare_baseline.compare (same code and seed as the SQLCoder comparison); it is not stored in analysis.json.
A7: Method: A question counts as solved if at least 2 of its 3 repeats are correct. Exact McNemar test (two-sided binomial on the discordant questions; n =
A8: only_first + only_second). Bootstrap CIs resample the 32 questions (10,000 resamples, seed 42). Bonferroni threshold = 0.05 / 10 comparisons.
A9: Sample size: N = 32 paired questions per comparison (3 repeats each); 96 trials per configuration.
A10: Limitations: Ten pairwise tests on one benchmark: p-values are not adjusted in the saved analysis (Bonferroni shown separately). With 32 questions, differences
A11: among Qwen3-1.7B / Llama 3.1 8B configurations are not statistically distinguishable. Wilson intervals treat repeats as independent and are too
A12: narrow.
A14: A. Accuracy with confidence intervals
A15: Configuration | B15: Trials | C15: Correct | D15: Accuracy | E15: Cluster-bootstrap CI low | F15: Cluster-bootstrap CI high | G15: Wilson CI low (naive, trial-level) | H15: Wilson CI high (naive, trial-level) | I15: Width: cluster bootstrap | J15: Width: Wilson (too narrow)
A16: P1 gemma3:1b + mxbai | B16: ='Model Comparison'!F17 | C16: ='Model Comparison'!G17 | D16: ='Model Comparison'!H17 | E16: ='Model Comparison'!I17 | F16: ='Model Comparison'!J17 | G16: 0.17413849 | H16: 0.34509998 | I16: =F16-E16 | J16: =H16-G16
A17: P2 gemma3:1b + MiniLM | B17: ='Model Comparison'!F18 | C17: ='Model Comparison'!G18 | D17: ='Model Comparison'!H18 | E17: ='Model Comparison'!I18 | F17: ='Model Comparison'!J18 | G17: 0.20107283 | H17: 0.37826084 | I17: =F17-E17 | J17: =H17-G17
A18: P3 qwen3:1.7b + mxbai | B18: ='Model Comparison'!F19 | C18: ='Model Comparison'!G19 | D18: ='Model Comparison'!H19 | E18: ='Model Comparison'!I19 | F18: ='Model Comparison'!J19 | G18: 0.85706807 | H18: 0.96423287 | I18: =F18-E18 | J18: =H18-G18
A19: P4 qwen3:1.7b + MiniLM | B19: ='Model Comparison'!F20 | C19: ='Model Comparison'!G20 | D19: ='Model Comparison'!H20 | E19: ='Model Comparison'!I20 | F19: ='Model Comparison'!J20 | G19: 0.81877666 | H19: 0.94242909 | I19: =F19-E19 | J19: =H19-G19
A20: P5 llama3.1:8b + mxbai | B20: ='Model Comparison'!F21 | C20: ='Model Comparison'!G21 | D20: ='Model Comparison'!H21 | E20: ='Model Comparison'!I21 | F20: ='Model Comparison'!J21 | G20: 0.83134502 | H20: 0.94989246 | I20: =F20-E20 | J20: =H20-G20
A23: B. Pairwise exact McNemar tests (saved analysis) with formula cross-check
A24: Configuration A | B24: Configuration B | C24: Paired questions (N) | D24: Solved only by A | E24: Solved only by B | F24: Discordant questions | G24: Exact McNemar p (saved) | H24: Exact McNemar p (formula check) | I24: Abs. difference | J24: Bonferroni-adjusted p | K24: Significant at 0.05 (unadjusted) | L24: Significant after Bonferroni
A25: P1 gemma3:1b + mxbai | B25: P2 gemma3:1b + MiniLM | C25: 32 | D25: 1 | E25: 2 | F25: =D25+E25 | G25: 1 | H25: =IF(F25=0,1,MIN(1,2*BINOM.DIST(MIN(D25,E25),F25,0.5,TRUE))) | I25: =ABS(G25-H25) | J25: =MIN(1,G25*COUNTA($A$25:$A$34)) | K25: =IF(G25<0.05,"yes","no") | L25: =IF(G25<0.05/COUNTA($A$25:$A$34),"yes","no")
A26: P1 gemma3:1b + mxbai | B26: P3 qwen3:1.7b + mxbai | C26: 32 | D26: 0 | E26: 22 | F26: =D26+E26 | G26: 4.7683716e-07 | H26: =IF(F26=0,1,MIN(1,2*BINOM.DIST(MIN(D26,E26),F26,0.5,TRUE))) | I26: =ABS(G26-H26) | J26: =MIN(1,G26*COUNTA($A$25:$A$34)) | K26: =IF(G26<0.05,"yes","no") | L26: =IF(G26<0.05/COUNTA($A$25:$A$34),"yes","no")
A27: P1 gemma3:1b + mxbai | B27: P4 qwen3:1.7b + MiniLM | C27: 32 | D27: 0 | E27: 20 | F27: =D27+E27 | G27: 1.9073486e-06 | H27: =IF(F27=0,1,MIN(1,2*BINOM.DIST(MIN(D27,E27),F27,0.5,TRUE))) | I27: =ABS(G27-H27) | J27: =MIN(1,G27*COUNTA($A$25:$A$34)) | K27: =IF(G27<0.05,"yes","no") | L27: =IF(G27<0.05/COUNTA($A$25:$A$34),"yes","no")
A28: P1 gemma3:1b + mxbai | B28: P5 llama3.1:8b + mxbai | C28: 32 | D28: 0 | E28: 21 | F28: =D28+E28 | G28: 9.5367432e-07 | H28: =IF(F28=0,1,MIN(1,2*BINOM.DIST(MIN(D28,E28),F28,0.5,TRUE))) | I28: =ABS(G28-H28) | J28: =MIN(1,G28*COUNTA($A$25:$A$34)) | K28: =IF(G28<0.05,"yes","no") | L28: =IF(G28<0.05/COUNTA($A$25:$A$34),"yes","no")
A29: P2 gemma3:1b + MiniLM | B29: P3 qwen3:1.7b + mxbai | C29: 32 | D29: 0 | E29: 21 | F29: =D29+E29 | G29: 9.5367432e-07 | H29: =IF(F29=0,1,MIN(1,2*BINOM.DIST(MIN(D29,E29),F29,0.5,TRUE))) | I29: =ABS(G29-H29) | J29: =MIN(1,G29*COUNTA($A$25:$A$34)) | K29: =IF(G29<0.05,"yes","no") | L29: =IF(G29<0.05/COUNTA($A$25:$A$34),"yes","no")
A30: P2 gemma3:1b + MiniLM | B30: P4 qwen3:1.7b + MiniLM | C30: 32 | D30: 1 | E30: 20 | F30: =D30+E30 | G30: 2.0980835e-05 | H30: =IF(F30=0,1,MIN(1,2*BINOM.DIST(MIN(D30,E30),F30,0.5,TRUE))) | I30: =ABS(G30-H30) | J30: =MIN(1,G30*COUNTA($A$25:$A$34)) | K30: =IF(G30<0.05,"yes","no") | L30: =IF(G30<0.05/COUNTA($A$25:$A$34),"yes","no")
A31: P2 gemma3:1b + MiniLM | B31: P5 llama3.1:8b + mxbai | C31: 32 | D31: 0 | E31: 20 | F31: =D31+E31 | G31: 1.9073486e-06 | H31: =IF(F31=0,1,MIN(1,2*BINOM.DIST(MIN(D31,E31),F31,0.5,TRUE))) | I31: =ABS(G31-H31) | J31: =MIN(1,G31*COUNTA($A$25:$A$34)) | K31: =IF(G31<0.05,"yes","no") | L31: =IF(G31<0.05/COUNTA($A$25:$A$34),"yes","no")
A32: P3 qwen3:1.7b + mxbai | B32: P4 qwen3:1.7b + MiniLM | C32: 32 | D32: 4 | E32: 2 | F32: =D32+E32 | G32: 0.6875 | H32: =IF(F32=0,1,MIN(1,2*BINOM.DIST(MIN(D32,E32),F32,0.5,TRUE))) | I32: =ABS(G32-H32) | J32: =MIN(1,G32*COUNTA($A$25:$A$34)) | K32: =IF(G32<0.05,"yes","no") | L32: =IF(G32<0.05/COUNTA($A$25:$A$34),"yes","no")
A33: P3 qwen3:1.7b + mxbai | B33: P5 llama3.1:8b + mxbai | C33: 32 | D33: 3 | E33: 2 | F33: =D33+E33 | G33: 1 | H33: =IF(F33=0,1,MIN(1,2*BINOM.DIST(MIN(D33,E33),F33,0.5,TRUE))) | I33: =ABS(G33-H33) | J33: =MIN(1,G33*COUNTA($A$25:$A$34)) | K33: =IF(G33<0.05,"yes","no") | L33: =IF(G33<0.05/COUNTA($A$25:$A$34),"yes","no")
A34: P4 qwen3:1.7b + MiniLM | B34: P5 llama3.1:8b + mxbai | C34: 32 | D34: 3 | E34: 4 | F34: =D34+E34 | G34: 1 | H34: =IF(F34=0,1,MIN(1,2*BINOM.DIST(MIN(D34,E34),F34,0.5,TRUE))) | I34: =ABS(G34-H34) | J34: =MIN(1,G34*COUNTA($A$25:$A$34)) | K34: =IF(G34<0.05,"yes","no") | L34: =IF(G34<0.05/COUNTA($A$25:$A$34),"yes","no")
A37: C. Paired accuracy difference with bootstrap CI - RECOMPUTED from saved trials (not in analysis.json)
A38: Difference = accuracy(B) - accuracy(A) over the 32 questions; CI = paired bootstrap over questions. Counts must equal block B (check column).
A39: Configuration A | B39: Configuration B | C39: Paired questions (N) | D39: Accuracy A (question mean) | E39: Accuracy B (question mean) | F39: Difference B - A | G39: 95% CI low | H39: 95% CI high | I39: Only A | J39: Only B | K39: Counts equal block B
A40: P1 gemma3:1b + mxbai | B40: P2 gemma3:1b + MiniLM | C40: 32 | D40: 0.25 | E40: 0.28125 | F40: =E40-D40 | G40: -0.0625 | H40: 0.125 | I40: 1 | J40: 2 | K40: =IF(AND(I40=D25,J40=E25),"match","MISMATCH")
A41: P1 gemma3:1b + mxbai | B41: P3 qwen3:1.7b + mxbai | C41: 32 | D41: 0.25 | E41: 0.92708333 | F41: =E41-D41 | G41: 0.51041667 | H41: 0.82291667 | I41: 0 | J41: 22 | K41: =IF(AND(I41=D26,J41=E26),"match","MISMATCH")
A42: P1 gemma3:1b + mxbai | B42: P4 qwen3:1.7b + MiniLM | C42: 32 | D42: 0.25 | E42: 0.89583333 | F42: =E42-D42 | G42: 0.47916667 | H42: 0.80208333 | I42: 0 | J42: 20 | K42: =IF(AND(I42=D27,J42=E27),"match","MISMATCH")
A43: P1 gemma3:1b + mxbai | B43: P5 llama3.1:8b + mxbai | C43: 32 | D43: 0.25 | E43: 0.90625 | F43: =E43-D43 | G43: 0.5 | H43: 0.8125 | I43: 0 | J43: 21 | K43: =IF(AND(I43=D28,J43=E28),"match","MISMATCH")
A44: P2 gemma3:1b + MiniLM | B44: P3 qwen3:1.7b + mxbai | C44: 32 | D44: 0.28125 | E44: 0.92708333 | F44: =E44-D44 | G44: 0.47916667 | H44: 0.80208333 | I44: 0 | J44: 21 | K44: =IF(AND(I44=D29,J44=E29),"match","MISMATCH")
A45: P2 gemma3:1b + MiniLM | B45: P4 qwen3:1.7b + MiniLM | C45: 32 | D45: 0.28125 | E45: 0.89583333 | F45: =E45-D45 | G45: 0.42708333 | H45: 0.79166667 | I45: 1 | J45: 20 | K45: =IF(AND(I45=D30,J45=E30),"match","MISMATCH")
A46: P2 gemma3:1b + MiniLM | B46: P5 llama3.1:8b + mxbai | C46: 32 | D46: 0.28125 | E46: 0.90625 | F46: =E46-D46 | G46: 0.46875 | H46: 0.78125 | I46: 0 | J46: 20 | K46: =IF(AND(I46=D31,J46=E31),"match","MISMATCH")
...

Sheet SQLCoder Comparison
A1: SQLCoder Comparison - external baseline
A2: QueryMind P5 vs Defog llama-3-sqlcoder-8b (Q4_K_M), full schema in the prompt, no retrieval
A4: Source: Counts are formulas over 'Raw Data'. Intervals, paired statistics and dialect-follow-up figures are copied from exp_runs/comparison_sqlcoder-vs-
A5: querymind/comparison.json and exp_runs/20261018T083111Z_sqlcoder-dialect-followup/followup.json; translation validation from
A6: exp_runs/20261018T083034Z_dialect-translation-validation/validation.json.
A7: Three arms: PRIMARY: QueryMind P5 87/96 vs SQLCoder original 51/96. SECONDARY, EXPLORATORY (post-processing, no model regeneration): SQLCoder dialect-adjusted
A8: 83/96. The adjusted arm only translates the PostgreSQL 'NULLS FIRST/LAST' ordering modifier (34 of the 96 saved statements contained it); everything
A9: else keeps its original outcome.
A10: Method: Same 32 questions, same database state, same scoring and decoding settings (temperature 0, seed 42). CIs and paired differences: bootstrap over
A11: questions. McNemar: exact, on questions solved in >= 2 of 3 repeats.
A12: Limitations: The dialect-adjusted result was defined after seeing the baseline errors (protocol fixed before it was run, validated separately) and is exploratory;
A13: it must not replace the primary comparison. SQLCoder was not tuned for MariaDB; QueryMind uses retrieval, SQLCoder the full schema. One run on one
... A16: A. Accuracy of the three arms (chart 5 data)
A17: Arm | B17: Analysis role | C17: Model / input | D17: Trials | E17: Correct results | F17: Execution-result accuracy | G17: 95% CI low (cluster bootstrap) | H17: 95% CI high (cluster bootstrap) | I17: SQL executed | J17: SQL execution success rate | K17: Database errors | L17: Hallucinated identifiers | M17: Hallucination rate | N17: CI error bar + (chart) | O17: CI error bar - (chart) | P17: Source
A18: QueryMind P5 (Llama 3.1 8B + mxbai) | B18: Primary | C18: llama3.1:8b + mxbai-embed-large (top-5 retrieval) | D18: =COUNTIFS('Raw Data'!$A$12:$A$662,"Expanded 32q",'Raw Data'!$C$12:$C$662,"P5") | E18: =COUNTIFS('Raw Data'!$A$12:$A$662,"Expanded 32q",'Raw Data'!$C$12:$C$662,"P5",'Raw Data'!$K$12:$K$662,1) | F18: =E18/D18 | G18: 0.78125 | H18: 1 | I18: =COUNTIFS('Raw Data'!$A$12:$A$662,"Expanded 32q",'Raw Data'!$C$12:$C$662,"P5",'Raw Data'!$J$12:$J$662,1) | J18: =I18/D18 | K18: =COUNTIFS('Raw Data'!$A$12:$A$662,"Expanded 32q",'Raw Data'!$C$12:$C$662,"P5",'Raw Data'!$I$12:$I$662,"db_error") | L18: =COUNTIFS('Raw Data'!$A$12:$A$662,"Expanded 32q",'Raw Data'!$C$12:$C$662,"P5",'Raw Data'!$L$12:$L$662,1) | M18: =L18/D18 | N18: =H18-F18 | O18: =F18-G18 | P18: exp_runs/comparison_sqlcoder-vs-querymind/comparison.json
A19: SQLCoder original | B19: Primary comparator | C19: Defog llama-3-sqlcoder-8b Q4_K_M (full schema) | D19: =COUNTIFS('Raw Data'!$A$12:$A$662,"SQLCoder 32q",'Raw Data'!$C$12:$C$662,"SQLCoder") | E19: =COUNTIFS('Raw Data'!$A$12:$A$662,"SQLCoder 32q",'Raw Data'!$C$12:$C$662,"SQLCoder",'Raw Data'!$K$12:$K$662,1) | F19: =E19/D19 | G19: 0.375 | H19: 0.71875 | I19: =COUNTIFS('Raw Data'!$A$12:$A$662,"SQLCoder 32q",'Raw Data'!$C$12:$C$662,"SQLCoder",'Raw Data'!$J$12:$J$662,1) | J19: =I19/D19 | K19: =COUNTIFS('Raw Data'!$A$12:$A$662,"SQLCoder 32q",'Raw Data'!$C$12:$C$662,"SQLCoder",'Raw Data'!$I$12:$I$662,"db_error") | L19: =COUNTIFS('Raw Data'!$A$12:$A$662,"SQLCoder 32q",'Raw Data'!$C$12:$C$662,"SQLCoder",'Raw Data'!$L$12:$L$662,1) | M19: =L19/D19 | N19: =H19-F19 | O19: =F19-G19 | P19: exp_runs/comparison_sqlcoder-vs-querymind/comparison.json
A20: SQLCoder dialect-adjusted (exploratory) | B20: Secondary exploratory (post-processing) | C20: Same saved SQL, NULLS FIRST/LAST translated | D20: 96 | E20: 83 | F20: =E20/D20 | G20: 0.73958333 | H20: 0.96875 | I20: 89 | J20: =I20/D20 | K20: 7 | L20: 4 | M20: =L20/D20 | N20: =H20-F20 | O20: =F20-G20 | P20: exp_runs/20261018T083111Z_sqlcoder-dialect-followup/followup.json
A40: Chart 5 data: table A columns F, N-O. Dark blue = QueryMind P5; grey = SQLCoder original (primary); orange = dialect-adjusted (secondary, exploratory). Source: exp_runs/20261018T083111Z_sqlcoder-dialect-followup/followup.json
A41: B. Paired comparisons (Arm 2 minus Arm 1), 32 questions
A42: Source: followup.json -> paired_primary / paired_secondary / paired_sqlcoder_original_vs_adjusted
A43: Comparison | B43: Arm 1 | C43: Arm 2 | D43: Paired questions (N) | E43: Arm 1 accuracy | F43: Arm 2 accuracy | G43: Difference (Arm 2 - Arm 1) | H43: 95% CI low (paired bootstrap) | I43: 95% CI high (paired bootstrap) | J43: Solved by both | K43: Solved only by Arm 1 | L43: Solved only by Arm 2 | M43: Solved by neither | N43: Discordant | O43: Exact McNemar p (saved) | P43: Exact McNemar p (formula check)
A44: PRIMARY: SQLCoder original vs QueryMind P5 | B44: QueryMind P5 | C44: SQLCoder original | D44: 32 | E44: 0.90625 | F44: 0.53125 | G44: =F44-E44 | H44: -0.5625 | I44: -0.15625 | J44: 15 | K44: 14 | L44: 2 | M44: 1 | N44: =K44+L44 | O44: 0.0041809082 | P44: =IF(N44=0,1,MIN(1,2*BINOM.DIST(MIN(K44,L44),N44,0.5,TRUE)))
A45: SECONDARY exploratory: SQLCoder adjusted vs QueryMind P5 | B45: QueryMind P5 | C45: SQLCoder adjusted | D45: 32 | E45: 0.90625 | F45: 0.86458333 | G45: =F45-E45 | H45: -0.17708333 | I45: 0.09375 | J45: 26 | K45: 3 | L45: 2 | M45: 1 | N45: =K45+L45 | O45: 1 | P45: =IF(N45=0,1,MIN(1,2*BINOM.DIST(MIN(K45,L45),N45,0.5,TRUE)))
A46: SECONDARY exploratory: SQLCoder adjusted vs SQLCoder original | B46: SQLCoder original | C46: SQLCoder adjusted | D46: 32 | E46: 0.53125 | F46: 0.86458333 | G46: =F46-E46 | H46: 0.17708333 | I46: 0.5 | J46: 17 | K46: 0 | L46: 11 | M46: 4 | N46: =K46+L46 | O46: 0.0009765625 | P46: =IF(N46=0,1,MIN(1,2*BINOM.DIST(MIN(K46,L46),N46,0.5,TRUE)))
A49: C. Failure analysis of SQLCoder original
A50: Source: comparison.json -> baseline.db_error_breakdown / executed_but_wrong_breakdown / difficulty_accuracy
A51: Item | B51: Trials
A52: Database errors: PostgreSQL-style syntax (mostly NULLS FIRST/LAST) | B52: 36
A53: Database errors: hallucinated identifier | B53: 3
A54: Executed but wrong: row-count mismatch | B54: 3
A55: Executed but wrong: content mismatch | B55: 3
A56: Trials with a NULLS FIRST/LAST modifier (dialect follow-up) | B56: 34
A59: D. Dialect translation: validation and outcome
A60: Source: validation.json (summary) and followup.json (translation_outcomes)
A61: Item | B61: Count / status
A62: Supported translation cases tested | B62: 16
A63: Supported cases passed (against an independent oracle) | B63: 16
A64: Unsupported cases tested | B64: 5
A65: Unsupported cases correctly refused (not translated) | B65: 5
A66: Cases where naively deleting the modifier gives a different result | B66: 13
...

Sheet Security Evaluation
A1: Security Evaluation - three SELECT-only layers
A2: experiment/security_evaluation.py on a disposable private MariaDB server (run 2026-10-18)
A4: Source: All 103 checks are copied from exp_runs/security_20261018T070742Z/results.json; summary counts are formulas over that table. The false-positive replay
A5: is RECOMPUTED from the saved benchmark trials with security.validate_sql. The post-hardening re-run is
A6: exp_runs/security_20261018T090823Z/results.json.
A7: Method: Layer 1 = database privileges (SELECT-only account, grant verification at login); layer 2 = question screening and lexical SQL validation; layer 3 =
A8: never-committed transaction with ROW_COUNT() check and rollback. Disposable data only; a privileged account was used solely to demonstrate layer 3.
A9: Sample size: 103 checks (16 layer 1, 45 layer 2, 13 layer 3, 18 application-flow, 10 live-model prompts, 1 final-state check).
A10: Limitations: Passing checks demonstrate the designed behaviour, not absolute security. The validator is lexical (not a SQL parser); the guard cannot undo DDL or
A11: non-transactional (MyISAM) changes (L3-10, L3-11 demonstrate this); a SELECT-only account still allows SLEEP (L1-16) and harmless tautology reads
A12: (L2-45). The live model complied with 6 of 10 hostile prompts.
A14: A. Summary by group (formulas over table E)
A15: Group | B15: Checks | C15: Passed | D15: Failed | E15: Pass rate
A16: Layer 1 - database privileges | B16: =COUNTIFS($B$50:$B$152,"Layer 1 - database privileges") | C16: =COUNTIFS($B$50:$B$152,"Layer 1 - database privileges",$G$50:$G$152,1) | D16: =B16-C16 | E16: =C16/B16
A17: Layer 2 - application validation | B17: =COUNTIFS($B$50:$B$152,"Layer 2 - application validation") | C17: =COUNTIFS($B$50:$B$152,"Layer 2 - application validation",$G$50:$G$152,1) | D17: =B17-C17 | E17: =C17/B17
A18: Layer 3 - post-execution guard | B18: =COUNTIFS($B$50:$B$152,"Layer 3 - post-execution guard") | C18: =COUNTIFS($B$50:$B$152,"Layer 3 - post-execution guard",$G$50:$G$152,1) | D18: =B18-C18 | E18: =C18/B18
A19: Application flow (all layers) | B19: =COUNTIFS($B$50:$B$152,"Application flow (all layers)") | C19: =COUNTIFS($B$50:$B$152,"Application flow (all layers)",$G$50:$G$152,1) | D19: =B19-C19 | E19: =C19/B19
A20: Live-model injection prompts | B20: =COUNTIFS($B$50:$B$152,"Live-model injection prompts") | C20: =COUNTIFS($B$50:$B$152,"Live-model injection prompts",$G$50:$G$152,1) | D20: =B20-C20 | E20: =C20/B20
A21: Final state | B21: =COUNTIFS($B$50:$B$152,"Final state") | C21: =COUNTIFS($B$50:$B$152,"Final state",$G$50:$G$152,1) | D21: =B21-C21 | E21: =C21/B21
A22: All checks | B22: =SUM(B16:B21) | C22: =SUM(C16:C21) | D22: =B22-C22 | E22: =C22/B22
A24: B. Check types (formulas over table E)
A25: Check type | B25: Checks | C25: Passed
A26: Direct statement refused by database privileges | B26: =COUNTIFS($C$50:$C$152,"Direct statement refused by database privileges") | C26: =COUNTIFS($C$50:$C$152,"Direct statement refused by database privileges",$G$50:$G$152,1)
A27: SQL validator: attack statement blocked | B27: =COUNTIFS($C$50:$C$152,"SQL validator: attack statement blocked") | C27: =COUNTIFS($C$50:$C$152,"SQL validator: attack statement blocked",$G$50:$G$152,1)
A28: Input keyword filter: dangerous question flagged | B28: =COUNTIFS($C$50:$C$152,"Input keyword filter: dangerous question flagged") | C28: =COUNTIFS($C$50:$C$152,"Input keyword filter: dangerous question flagged",$G$50:$G$152,1)
A29: Modification detected / guard behaviour | B29: =COUNTIFS($C$50:$C$152,"Modification detected / guard behaviour") | C29: =COUNTIFS($C$50:$C$152,"Modification detected / guard behaviour",$G$50:$G$152,1)
A30: Documented limitation demonstrated | B30: =COUNTIFS($C$50:$C$152,"Documented limitation demonstrated") | C30: =COUNTIFS($C$50:$C$152,"Documented limitation demonstrated",$G$50:$G$152,1)
A32: C. Runs of the security evaluation (provenance)
A33: Run | B33: Checks | C33: Passed | D33: Note
A34: security_20261018T070414Z | B34: 92 | C34: 91 | D34: SUPERSEDED: L3-02 failed because of test data (a balance already 0); test corrected, not the code
A35: security_20261018T070742Z | B35: 103 | C35: 103 | D35: Used in this workbook (full run incl. live model)
A36: security_20261018T090823Z | B36: 93 | C36: 93 | D36: Re-run after web hardening, --skip-llm (the 10 live-model prompts excluded)
A38: D. False-positive replay (RECOMPUTED from saved trials; not in results.json)
A39: Item | B39: Trials
A40: Trials with generated SQL (480 expanded + 75 bridge) | B40: 555
A41: Of which correct | B41: 386
A42: Correct statements blocked by the validator (false positives) | B42: 0
A43: Incorrect statements rejected by the validator | B43: 6
A44: Overhead (validator ~0.03-0.08 ms, transaction guard +0.5-1 ms per query) is quoted in docs/SECURITY_LAYERS.md, but no raw timing file was saved: NOT included as a measured result.
A45: Live model (llama3.1:8b): 6 of 9 hostile prompts produced a harmful or privileged statement (counted from the model_output column of INJ-01..INJ-10); every one was stopped by layer 2 and no data changed.
...

Sheet Original vs Expanded
A1: Original vs Expanded - historical pilot, 75-trial bridge, expanded benchmark
A2: Three evaluations with different questions, scoring and sampling: read them as separate studies
A4: WARNING: The historical five-question pilot (Nov 2025) is NOT directly comparable with the new results: it used Ollama's default sampling, one run per
A5: question, an older 'result match' rule and different timing code. It is shown only as a record. The bridge run re-measures the same five questions
A6: with the current framework.
A7: Source: Section A: exp_com_res/summary_report.json (historical). Section B: exp_runs/analysis_bridge-gold5/analysis.json and Raw Data. Section C: links to
A8: 'Model Comparison'.
A9: Sample size: A: 5 questions x 1 run per configuration. B: 5 questions x 3 repeats = 15 trials per configuration (75 in total). C: 32 questions x 3 repeats = 96
A10: trials per configuration (480).
A11: Limitations: Five questions cannot separate configurations (ceiling effect); the 32-question benchmark can. Bridge and expanded runs use the same code and database
A12: state; the pilot does not.
A14: A. HISTORICAL PILOT (5 questions, 1 run each, older scoring) - not comparable with sections B and C
A15: Configuration | B15: Questions | C15: Matching results | D15: Result match rate (older rule) | E15: Mean context time (s) | F15: Mean generation time (s) | G15: Context + generation (s) | H15: Source
A16: P1 gemma3:1b + mxbai | B16: 5 | C16: 3 | D16: =C16/B16 | E16: 0.1412 | F16: 5.1932 | G16: =E16+F16 | H16: exp_com_res/results_gemma3_1b_mxbai-embed-large_latest.json
A17: P2 gemma3:1b + MiniLM | B17: 5 | C17: 2 | D17: =C17/B17 | E17: 0.0318 | F17: 4.2032 | G17: =E17+F17 | H17: exp_com_res/results_gemma3_1b_all-minilm_latest.json
A18: P3 qwen3:1.7b + mxbai | B18: 5 | C18: 3 | D18: =C18/B18 | E18: 0.1502 | F18: 6.6862 | G18: =E18+F18 | H18: exp_com_res/results_qwen3_1.7b_mxbai-embed-large_latest.json
A19: P4 qwen3:1.7b + MiniLM | B19: 5 | C19: 3 | D19: =C19/B19 | E19: 0.032 | F19: 4.5154 | G19: =E19+F19 | H19: exp_com_res/results_qwen3_1.7b_all-minilm_latest.json
A20: P5 llama3.1:8b + mxbai | B20: 5 | C20: 5 | D20: =C20/B20 | E20: 4.3186 | F20: 28.9736 | G20: =E20+F20 | H20: exp_com_res/results_llama3.1_8b_mxbai-embed-large_latest.json
A23: B. BRIDGE RUN (same 5 questions, current framework, 3 repeats)
A24: Configuration | B24: Questions | C24: Repeats | D24: Trials | E24: Correct results | F24: Execution-result accuracy | G24: 95% CI low (cluster bootstrap) | H24: 95% CI high (cluster bootstrap) | I24: SQL execution success rate | J24: Legacy match rate (historical rule, re-measured) | K24: End-to-end mean (s) | L24: Source
A25: P1 gemma3:1b + mxbai | B25: 5 | C25: 3 | D25: =COUNTIFS('Raw Data'!$A$12:$A$662,"Bridge 5q",'Raw Data'!$C$12:$C$662,"P1") | E25: =COUNTIFS('Raw Data'!$A$12:$A$662,"Bridge 5q",'Raw Data'!$C$12:$C$662,"P1",'Raw Data'!$K$12:$K$662,1) | F25: =E25/D25 | G25: 1 | H25: 1 | I25: =COUNTIFS('Raw Data'!$A$12:$A$662,"Bridge 5q",'Raw Data'!$C$12:$C$662,"P1",'Raw Data'!$J$12:$J$662,1)/D25 | J25: 0.8 | K25: =AVERAGEIFS('Raw Data'!$S$12:$S$662,'Raw Data'!$A$12:$A$662,"Bridge 5q",'Raw Data'!$C$12:$C$662,"P1") | L25: exp_runs/analysis_bridge-gold5/analysis.json
A26: P2 gemma3:1b + MiniLM | B26: 5 | C26: 3 | D26: =COUNTIFS('Raw Data'!$A$12:$A$662,"Bridge 5q",'Raw Data'!$C$12:$C$662,"P2") | E26: =COUNTIFS('Raw Data'!$A$12:$A$662,"Bridge 5q",'Raw Data'!$C$12:$C$662,"P2",'Raw Data'!$K$12:$K$662,1) | F26: =E26/D26 | G26: 0.8 | H26: 1 | I26: =COUNTIFS('Raw Data'!$A$12:$A$662,"Bridge 5q",'Raw Data'!$C$12:$C$662,"P2",'Raw Data'!$J$12:$J$662,1)/D26 | J26: 0.73333333 | K26: =AVERAGEIFS('Raw Data'!$S$12:$S$662,'Raw Data'!$A$12:$A$662,"Bridge 5q",'Raw Data'!$C$12:$C$662,"P2") | L26: exp_runs/analysis_bridge-gold5/analysis.json
A27: P3 qwen3:1.7b + mxbai | B27: 5 | C27: 3 | D27: =COUNTIFS('Raw Data'!$A$12:$A$662,"Bridge 5q",'Raw Data'!$C$12:$C$662,"P3") | E27: =COUNTIFS('Raw Data'!$A$12:$A$662,"Bridge 5q",'Raw Data'!$C$12:$C$662,"P3",'Raw Data'!$K$12:$K$662,1) | F27: =E27/D27 | G27: 1 | H27: 1 | I27: =COUNTIFS('Raw Data'!$A$12:$A$662,"Bridge 5q",'Raw Data'!$C$12:$C$662,"P3",'Raw Data'!$J$12:$J$662,1)/D27 | J27: 0 | K27: =AVERAGEIFS('Raw Data'!$S$12:$S$662,'Raw Data'!$A$12:$A$662,"Bridge 5q",'Raw Data'!$C$12:$C$662,"P3") | L27: exp_runs/analysis_bridge-gold5/analysis.json
A28: P4 qwen3:1.7b + MiniLM | B28: 5 | C28: 3 | D28: =COUNTIFS('Raw Data'!$A$12:$A$662,"Bridge 5q",'Raw Data'!$C$12:$C$662,"P4") | E28: =COUNTIFS('Raw Data'!$A$12:$A$662,"Bridge 5q",'Raw Data'!$C$12:$C$662,"P4",'Raw Data'!$K$12:$K$662,1) | F28: =E28/D28 | G28: 0.8 | H28: 1 | I28: =COUNTIFS('Raw Data'!$A$12:$A$662,"Bridge 5q",'Raw Data'!$C$12:$C$662,"P4",'Raw Data'!$J$12:$J$662,1)/D28 | J28: 0 | K28: =AVERAGEIFS('Raw Data'!$S$12:$S$662,'Raw Data'!$A$12:$A$662,"Bridge 5q",'Raw Data'!$C$12:$C$662,"P4") | L28: exp_runs/analysis_bridge-gold5/analysis.json
A29: P5 llama3.1:8b + mxbai | B29: 5 | C29: 3 | D29: =COUNTIFS('Raw Data'!$A$12:$A$662,"Bridge 5q",'Raw Data'!$C$12:$C$662,"P5") | E29: =COUNTIFS('Raw Data'!$A$12:$A$662,"Bridge 5q",'Raw Data'!$C$12:$C$662,"P5",'Raw Data'!$K$12:$K$662,1) | F29: =E29/D29 | G29: 1 | H29: 1 | I29: =COUNTIFS('Raw Data'!$A$12:$A$662,"Bridge 5q",'Raw Data'!$C$12:$C$662,"P5",'Raw Data'!$J$12:$J$662,1)/D29 | J29: 0.8 | K29: =AVERAGEIFS('Raw Data'!$S$12:$S$662,'Raw Data'!$A$12:$A$662,"Bridge 5q",'Raw Data'!$C$12:$C$662,"P5") | L29: exp_runs/analysis_bridge-gold5/analysis.json
A30: Bridge total trials | D30: =SUM(D25:D29) | E30: =SUM(E25:E29)
A33: C. EXPANDED BENCHMARK (32 questions) next to the bridge (chart 6 data)
A34: Linked by formula to 'Model Comparison' and section B
A35: Configuration | B35: Bridge accuracy (5 questions, 15 trials) | C35: Expanded accuracy (32 questions, 96 trials) | D35: Difference (expanded - bridge) | E35: Expanded trials | F35: Expanded correct
A36: P1 gemma3:1b + mxbai | B36: =F25 | C36: ='Model Comparison'!H17 | D36: =C36-B36 | E36: ='Model Comparison'!F17 | F36: ='Model Comparison'!G17
A37: P2 gemma3:1b + MiniLM | B37: =F26 | C37: ='Model Comparison'!H18 | D37: =C37-B37 | E37: ='Model Comparison'!F18 | F37: ='Model Comparison'!G18
A38: P3 qwen3:1.7b + mxbai | B38: =F27 | C38: ='Model Comparison'!H19 | D38: =C38-B38 | E38: ='Model Comparison'!F19 | F38: ='Model Comparison'!G19
A39: P4 qwen3:1.7b + MiniLM | B39: =F28 | C39: ='Model Comparison'!H20 | D39: =C39-B39 | E39: ='Model Comparison'!F20 | F39: ='Model Comparison'!G20
A40: P5 llama3.1:8b + mxbai | B40: =F29 | C40: ='Model Comparison'!H21 | D40: =C40-B40 | E40: ='Model Comparison'!F21 | F40: ='Model Comparison'!G21
A60: Chart 6 data: section C (formulas). The historical pilot is deliberately not plotted. Source: exp_runs/analysis_bridge-gold5/analysis.json and exp_runs/analysis_paper-v1_final/analysis.json

Sheet Raw Data
A1: Raw Data - one row per trial
A2: Trial-level values copied from trials.jsonl of every run used in this workbook
A4: Source: exp_runs/<run>/trials.jsonl for the five expanded-benchmark runs (paper-v1-P1..P5, 480 trials), the five bridge runs (bridge-gold5-P1..P5, 75 trials)
A5: and the SQLCoder baseline (sqlcoder-8b-baseline, 96 trials). Nothing was edited.
A6: Method: Correct = result_correct (execution-result equivalence with the reference query on the saved database state). Hallucinated = database error classified
A7: 'hallucinated_identifier' by experiment/analyze_results.classify_db_error. Times are seconds. Blank cells = not measured (SQLCoder has no retrieval;
A8: Ollama internals were only recorded for SQLCoder).
